<?xml version="1.0"?>
<robot xmlns:xacro="http://wiki.ros.org/xacro">
  <xacro:macro name="kuka_kr150r3100" params="prefix">
    <xacro:include filename="$(find kuka_resources)/urdf/common_materials.xacro"/>
    <!-- LINKS -->
    <!-- base link -->
    <link name="${prefix}base_link">
      <visual>
        <origin rpy="0 0 0" xyz="0 0 0"/>
        <geometry>
          <mesh filename="package://kr150_description/meshes/kr150r3100_2/visual/base_link.stl" />
        </geometry>
        <xacro:material_kuka_pedestal />
      </visual>
      <collision>
        <origin rpy="0 0 0" xyz="0 0 0"/>
        <geometry>
          <mesh filename="package://kr150_description/meshes/kr150r3100_2/collision/base_link.stl" />
        </geometry>
      </collision>
      <inertial>
        <mass value="23.085357"/>
        <origin rpy="0.0 0.0 0.0" xyz="0.007579 0.000017 0.180670"/>
        <inertia ixx="0.343576" ixy="-0.000062" ixz="-0.002079" iyy="0.336217" iyz="-0.000014" izz="0.334050"/>
</inertial>
    </link>
    <!-- link 1 (A1) -->
    <link name="${prefix}link_1">
      <visual>
        <origin xyz="0 0 0" rpy="0 0 0"/>
        <geometry>
          <mesh filename="package://kr150_description/meshes/kr150r3100_2/visual/link_1.stl" />
        </geometry>
        <xacro:material_kuka_orange />
      </visual>
      <collision>
        <origin xyz="0 0 0" rpy="0 0 0"/>
        <geometry>
          <mesh filename="package://kr150_description/meshes/kr150r3100_2/collision/link_1.stl" />
        </geometry>
      </collision>
      <inertial>
        <mass value="45.357763"/>
        <origin rpy="0.0 0.0 0.0" xyz="0.085479 -0.002547 -0.040488"/>
        <inertia ixx="0.839141" ixy="0.022637" ixz="0.162457" iyy="1.030146" iyz="0.027416" izz="1.064698"/>
</inertial>
    </link>
    <!-- link 2 -->
    <link name="${prefix}link_2">
      <visual>
        <origin xyz="0 0 0" rpy="0 0 0"/>
        <geometry>
          <mesh filename="package://kr150_description/meshes/kr150r3100_2/visual/link_2.stl"/>
        </geometry>
        <xacro:material_kuka_orange />
      </visual>
      <collision>
        <origin xyz="0 0 0" rpy="0 0 0"/>
        <geometry>
          <mesh filename="package://kr150_description/meshes/kr150r3100_2/collision/link_2.stl"  />
        </geometry>
      </collision>
      <inertial>
        <mass value="51.266495"/>
        <origin rpy="0.0 0.0 0.0" xyz="-0.000002 0.264164 0.347704"/>
        <inertia ixx="5.272800" ixy="0.000010" ixz="0.000017" iyy="5.536809" iyz="-0.008261" izz="0.486191"/>
</inertial>
    </link>
    <!-- link 3 -->
    <link name="${prefix}link_3">
      <visual>
        <origin xyz="0 0 0" rpy="0 0 0"/>
        <geometry>
          <mesh filename="package://kr150_description/meshes/kr150r3100_2/visual/link_3.stl" />
        </geometry>
        <xacro:material_kuka_orange />
      </visual>
      <collision>
        <origin xyz="0 0 0" rpy="0 0 0"/>
        <geometry>
          <mesh filename="package://kr150_description/meshes/kr150r3100_2/collision/link_3.stl"  />
        </geometry>
      </collision>
      <inertial>
        <mass value="19.754401"/>
        <origin rpy="0.0 0.0 0.0" xyz="-0.000255 0.016478 -0.003819"/>
        <inertia ixx="0.249388" ixy="-0.004901" ixz="0.004825" iyy="0.211780" iyz="0.000574" izz="0.238488"/>
</inertial>
    </link>
    <!-- link 4 -->
    <link name="${prefix}link_4">
      <visual>
        <origin xyz="0 0 0" rpy="0 0 0"/>
        <geometry>
          <mesh filename="package://kr150_description/meshes/kr150r3100_2/visual/link_4.stl" />
        </geometry>
        <xacro:material_kuka_orange />
      </visual>
      <collision>
        <origin xyz="0 0 0" rpy="0 0 0"/>
        <geometry>
          <mesh filename="package://kr150_description/meshes/kr150r3100_2/collision/link_4.stl"  />
        </geometry>
      </collision>
      <inertial>
        <mass value="15.287896"/>
        <origin rpy="0.0 0.0 0.0" xyz="-0.015515 0.000164 0.340348"/>
        <inertia ixx="0.331593" ixy="0.000055" ixz="-0.010688" iyy="0.320895" iyz="0.000058" izz="0.086557"/>
</inertial>
    </link>
    <!-- link 5 -->
    <link name="${prefix}link_5">
      <visual>
        <origin xyz="0 0 0" rpy="0 0 0"/>
        <geometry>
          <mesh filename="package://kr150_description/meshes/kr150r3100_2/visual/link_5.stl" />
        </geometry>
        <xacro:material_kuka_orange />
      </visual>
      <collision>
        <origin xyz="0 0 0" rpy="0 0 0"/>
        <geometry>
          <mesh filename="package://kr150_description/meshes/kr150r3100_2/collision/link_5.stl" />
        </geometry>
      </collision>
      <inertial>
        <mass value="0.548088"/>
        <origin rpy="0.0 0.0 0.0" xyz="0.000000 -0.000347 0.023671"/>
        <inertia ixx="0.000876" ixy="0.000000" ixz="0.000000" iyy="0.000889" iyz="0.000005" izz="0.000412"/>
</inertial>
    </link>
    <!-- link 6 -->
    <link name="${prefix}link_6">
      <visual>
        <origin xyz="0 0 0" rpy="0 0 0"/>
        <geometry>
          <mesh filename="package://kr150_description/meshes/kr150r3100_2/visual/link_6.stl" />
        </geometry>
        <xacro:material_kuka_orange />
      </visual>
      <collision>
        <origin xyz="0 0 0" rpy="0 0 0"/>
        <geometry>
          <mesh filename="package://kr150_description/meshes/kr150r3100_2/collision/link_6.stl" />
        </geometry>
      </collision>
      <inertial>
        <mass value="0.038484"/>
        <origin rpy="0.0 0.0 0.0" xyz="-0.000245 0.000000 -0.007626"/>
        <inertia ixx="0.000011" ixy="0.000000" ixz="0.000000" iyy="0.000011" iyz="0.000000" izz="0.000021"/>
</inertial>
    </link>
    <!-- END LINKS -->

    <!-- JOINTS -->
    <!-- joint 1 (A1) -->
    <joint name="${prefix}joint_a1" type="revolute">
      <origin xyz="0 0 0.645" rpy="0 0 0"/>
      <parent link="${prefix}base_link"/>
      <child link="${prefix}link_1"/>
      <axis xyz="0 0 -1"/>
      <limit effort="692" lower="${radians(-185)}" upper="${radians(185)}" velocity="${radians(105)}"/>
      <dynamics damping="0.0" friction="0.0"/>
    </joint>
    <!-- joint 2 (A2) -->
    <joint name="${prefix}joint_a2" type="revolute">
      <origin xyz="0.33 0 0" rpy="0 0 0"/>
      <parent link="${prefix}link_1"/>
      <child link="${prefix}link_2"/>
      <axis xyz="0 1 0"/>
      <limit effort="574" lower="${radians(-140)}" upper="${radians(-5)}" velocity="${radians(107)}"/>
      <dynamics damping="0.0" friction="0.0"/>
    </joint>
    <!-- joint 3 (A3) -->
    <joint name="${prefix}joint_a3" type="revolute">
      <origin xyz="1.350 0 0" rpy="0 0 0"/>
      <parent link="${prefix}link_2"/>
      <child link="${prefix}link_3"/>
      <axis xyz="0 1 0"/>
      <limit effort="242" lower="${radians(-120)}" upper="${radians(168)}" velocity="${radians(114)}"/>
      <dynamics damping="0.0" friction="0.0"/>
    </joint>
    <!-- joint 4 (A4) -->
    <joint name="${prefix}joint_a4" type="revolute">
      <origin xyz="1.420 0 0.115" rpy="0 0 0"/>
      <parent link="${prefix}link_3"/>
      <child link="${prefix}link_4"/>
      <axis xyz="-1 0 0"/>
      <limit effort="58" lower="${radians(-350)}" upper="${radians(350)}" velocity="${radians(190)}"/>
      <dynamics damping="0.0" friction="0.0"/>
    </joint>
    <!-- joint 5 (A5) -->
    <joint name="${prefix}joint_a5" type="revolute">
      <origin xyz="0 0 0" rpy="0 0 0"/>
      <parent link="${prefix}link_4"/>
      <child link="${prefix}link_5"/>
      <axis xyz="0 1 0"/>
      <limit effort="29" lower="${radians(-125)}" upper="${radians(125)}" velocity="${radians(180)}"/>
      <dynamics damping="0.0" friction="0.0"/>
    </joint>
    <!-- joint 6 (A6) -->
    <joint name="${prefix}joint_a6" type="revolute">
      <origin xyz="0.215 0 0" rpy="0 0 0"/>
      <parent link="${prefix}link_5"/>
      <child link="${prefix}link_6"/>
      <axis xyz="-1 0 0"/>
      <limit effort="29" lower="${radians(-350)}" upper="${radians(350)}" velocity="${radians(260)}"/>
      <dynamics damping="0.0" friction="0.0"/>
    </joint>
    
    <!-- ROS-Industrial 'base' frame: base_link to KUKA $ROBROOT coordinate system transform -->
    <link name="${prefix}base" />
    <joint name="${prefix}base_link-base" type="fixed">
      <origin xyz="0 0 0" rpy="0 0 0"/>
      <parent link="${prefix}base_link"/>
      <child link="${prefix}base"/>
    </joint>

    <!-- ROS-Industrial 'flange' frame: attachment point for EEF models -->
    <link name="${prefix}flange" />
    <joint name="${prefix}joint_6-flange" type="fixed">
      <origin xyz="0 0 0" rpy="0 0 0" />
      <parent link="${prefix}link_6" />
      <child link="${prefix}flange" />
    </joint>

    <!-- ROS-Industrial 'tool0' frame: all-zeros tool frame -->
    <!-- This frame corresponds to the $FLANGE coordinate system in KUKA KRC controllers. -->
    <link name="${prefix}tool0"/>
    <joint name="${prefix}flange-tool0" type="fixed">
      <parent link="${prefix}flange"/>
      <child link="${prefix}tool0"/>
      <origin xyz="0 0 0" rpy="0 ${radians(90)} 0"/>
    </joint>
    
  </xacro:macro>
</robot>
